Workbook

Sheet Datos
B1: Según el estatuto tributario de los impuestos administrados por la dirección general de impuestos nacionales artículo 137, hay un límite a la deducción por depreciación. Para construcciones y edificaciones (obras civiles), la tasa de depreciación fiscal anual es del 2.22%, para maquinaria y equipos, es del 10% y para muebles y enseres es del 10%. Entonces como la tasa se calcula como tasa=1/vida útil, se puede despejar la vida útil como 1/tasa. Para maquinaria y equipos la tasa máxima es 10%, por lo que 1/0.1 = 10 años es la vida útil mínima que se puede ponerle a estos activos. Dado que 20 años son más que 10 años, es totalmente viable poner 20 años como vida útil a la maquinaria y equipo. Esta misma vida útil se puede poner al montaje y el transporte de equipos ya que son costos de puesta en marcha que se capitalizan como parte del costo de la maquinaria. Para los muebles y enseres y obras civiles, utilizaremos la vida útil mínima. | C1: https://leyes.co/se_expide_el_estatuto_tributario_de_los_impuestos_administrados_por_la_direccion_general_de_impuestos_nacionales/137.htm
B3: Inversión en Activos Fijos Inicial
B4: Inversión inicial | C4: millones de COP | D4: Tasa máxima | E4: Vida útil | F4: Nota
B5: Maquinaria y Equipos | C5: 8500 | D5: 0.1 | E5: 20 | F5: Sacado de la nota 13 del PDF
B6: Muebles y Enseres | C6: 2500 | D6: 0.1 | E6: =1/D6 -> 10 | F6: Vida útil mínima
B7: Obras Civiles | C7: 900 | D7: 0.022 | E7: =1/D7 -> 45.454545 | F7: Vida útil mínima
B8: Montaje | C8: 850 | D8: N/A | E8: 20 | F8: Sacado de la nota 13 del PDF
B9: Transporte de Equipos | C9: 1250 | D9: N/A | E9: 20 | F9: Sacado de la nota 13 del PDF
B10: Total Capex Activos Fijos | C10: =SUM(C5:C9) -> 14000
B11: Inversión inicial | C11: millones de COP | D11: ¿Costo hundido?
B12: Estudio de Mercado | C12: 5000 | D12: SI
B13: Estudios Técnicos | C13: 2500 | D13: SI
B14: Costo Avalúo Bodega | C14: 420 | D14: SI
B15: Total | C15: =SUM(C12:C14) -> 7920
B17: Tasa impositiva Colombia | C17: 0.35
B18: Valor en libros de la bodega | C18: 20000 | D18: millones | E18: Pagina 4
B19: Canon arrendamiento anual (10% VM) | C19: =C20*0.1 -> 2800 | D19: millones | E19: Pagina 4 Nota 9
B20: Valor de venta esperado | C20: 28000 | D20: millones | E20: Pagina 5
B21: Mantenimiento sobre activos | C21: 0.055 | D21: de los ingresos
B22: Costo de materia prima | C22: 1600000 | D22: la tonelada
B23: Crecimiento real materia prima | C23: 0.02
B24: Renovación (overhaul) AÑO 5 | C24: 0.7 | D24: del valor inicial de la adquisición | E24: Pagina 5 Nota 13
B25: Porcentaje de seguro | C25: 0.1 | D25: sobre el valor inicial de los activos | E25: Pagina 6
B26: Gastos operacionales variables | C26: 0.25 | D26: sobre los ingresos
B27: Comisiones | C27: 0.02 | D27: sobre los ingresos
B28: CXC (días) | C28: 30 | E28: Pagina 7
B29: CXP (días) | C29: 90
B30: Precio de venta | C30: 6500000 | D30: millones
B31: Crecimiento real anual | C31: 0.06
B32: Política de crédito sugerido por área comercial | C32: 120 | D32: días en vez de 95
B33: Aumento esperado en ventas atado a la política sugerida | C33: 0.02
B34: %E | C34: 0.4 | D34: porcentaje de equity
B35: %D | C35: 0.6 | D35: porcentaje de deuda
B36: Política de dividendos | C36: 0.9

Sheet Nómina
A2: Cargo | B2: No | C2: Salario / Mes (millones de COP) | D2: Salario anual (millones de COP) | E2: ¿Es parte de la producción?
A3: Gerente del Proyecto | B3: 1 | C3: 15 | D3: =C3*12*B3 -> 180 | E3: NO | G3: Salario anual de nómina operativa | H3: =SUMIF(E3:E17,"SI",D3:D17)*1000000 -> 300000000 | I3: millones de COP
A4: Jefe de Producción | B4: 1 | C4: 9.5 | D4: =C4*12*B4 -> 114 | E4: SI | G4: Salario anual de nómina administrativa | H4: =SUMIF(E3:E17,"NO",D3:D17)*1000000 -> 1488000000 | I4: millones de COP
A5: Secretaria | B5: 1 | C5: 3.5 | D5: =C5*12*B5 -> 42 | E5: NO
A6: Director Financiero | B6: 1 | C6: 15 | D6: =C6*12*B6 -> 180 | E6: NO
A7: Director de Gestión Humana | B7: 1 | C7: 12 | D7: =C7*12*B7 -> 144 | E7: NO
A8: Contador | B8: 1 | C8: 10 | D8: =C8*12*B8 -> 120 | E8: NO
A9: Ingeniero de mantenimiento | B9: 1 | C9: 7.5 | D9: =C9*12*B9 -> 90 | E9: SI
A10: Analista de Gestión Humana | B10: 1 | C10: 4 | D10: =C10*12*B10 -> 48 | E10: NO
A11: Auxiliares operativos | B11: 2 | C11: 4 | D11: =C11*12*B11 -> 96 | E11: SI
A12: Auxiliar administrativo | B12: 1 | C12: 4 | D12: =C12*12*B12 -> 48 | E12: NO
A13: Auxiliar contable | B13: 1 | C13: 3.5 | D13: =C13*12*B13 -> 42 | E13: NO
A14: Jefe de Salud y Seguridad en el trabajo | B14: 1 | C14: 8 | D14: =C14*12*B14 -> 96 | E14: NO
A15: Auxiliar Salud y Seguridad en el trabajo | B15: 1 | C15: 4 | D15: =C15*12*B15 -> 48 | E15: NO
A16: Asesores comerciales | B16: 5 | C16: 7 | D16: =C16*12*B16 -> 420 | E16: NO
A17: Personal de vigilancia | B17: 4 | C17: 2.5 | D17: =C17*12*B17 -> 120 | E17: NO
A18: Total | B18: =SUM(B3:B17) -> 23 | C18: =SUM(C3:C17) -> 109.5 | D18: =SUM(D3:D17) -> 1788
A20: Factor salarial | B20: 4.5
A22: Nota: este factor salarial se usa para saber cuánto cobrarle al cliente por hora/mes de un profesional, como no estamos vendiendo tiempo de personas y estamos vendiendo toneladas de aluminio, este valor no aplica
A24: Pagina 6_Nota 15 = Incremento salarial con base en la inflación al cierre del año inmediatamente anterior

Sheet Costo de oportunidad
A4: Mantenimiento de bodega | B4: 0.03
A5: Multa por quitar arrendadores
B7: Año 1 | C7: Año 2 | D7: Año 3 | E7: Año 4 | F7: Año 5 | G7: Año 6 | H7: Año 7 | I7: Año 8 | J7: Año 9 | K7: Año 10
A8: Consecutivo | B8: 1 | C8: 2 | D8: 3 | E8: 4 | F8: 5 | G8: 6 | H8: 7 | I8: 8 | J8: 9 | K8: 10
A9: Inflación | B9: 0.064 | C9: 0.037 | D9: 0.03525 | E9: 0.0335 | F9: 0.03175 | G9: 0.03 | H9: 0.037071068 | I9: 0.04 | J9: 0.037071068 | K9: 0.03
A10: Canón | B10: =Datos!C19*1000000 -> 2800000000 | C10: =B10*(1+B9) -> 2979200000 | D10: =C10*(1+C9) -> 3089430400 | E10: =D10*(1+D9) -> 3.1983328e+09 | F10: =E10*(1+E9) -> 3.305477e+09 | G10: =F10*(1+F9) -> 3.4104259e+09 | H10: =G10*(1+G9) -> 3.5127386e+09 | I10: =H10*(1+H9) -> 3.6429596e+09 | J10: =I10*(1+I9) -> 3.788678e+09 | K10: =J10*(1+J9) -> 3.9291283e+09
B11: =B10*$B$4 -> 84000000 | C11: =C10*$B$4 -> 89376000 | D11: =D10*$B$4 -> 92682912 | E11: =E10*$B$4 -> 95949985 | F11: =F10*$B$4 -> 99164309 | G11: =G10*$B$4 -> 1.0231278e+08 | H11: =H10*$B$4 -> 1.0538216e+08 | I11: =I10*$B$4 -> 1.0928879e+08 | ... K11: =K10*$B$4 -> 1.1787385e+08
A12: Flujo de caja | B12: =B10-B11 -> 2716000000 | C12: =C10-C11 -> 2889824000 | D12: =D10-D11 -> 2996747488 | E12: =E10-E11 -> 3.1023828e+09 | F12: =F10-F11 -> 3.2063127e+09 | G12: =G10-G11 -> 3.3081131e+09 | H12: =H10-H11 -> 3.4073565e+09 | I12: =I10-I11 -> 3.5336708e+09 | ... K12: =K10-K11 -> 3.8112545e+09
A13: Factor de descuento | B13: =1/(1+B9)^B8 -> 0.93984962 | C13: =1/(1+C9)^C8 -> 0.92991336 | D13: =1/(1+D9)^D8 -> 0.90128944 | E13: =1/(1+E9)^E8 -> 0.87651242 | F13: =1/(1+F9)^F8 -> 0.855318 | G13: =1/(1+G9)^G8 -> 0.83748426 | H13: =1/(1+H9)^H8 -> 0.77506901 | I13: =1/(1+I9)^I8 -> 0.73069021 | ... K13: =1/(1+K9)^K8 -> 0.74409391
A14: Flujo de caja descontado | B14: =B12*B13 -> 2.5526316e+09 | C14: =C12*C13 -> 2.6872859e+09 | D14: =D12*D13 -> 2.7009369e+09 | E14: =E12*E13 -> 2.7192771e+09 | F14: =F12*F13 -> 2.7424169e+09 | G14: =G12*G13 -> 2.7704926e+09 | H14: =H12*H13 -> 2.6409364e+09 | I14: =I12*I13 -> 2.5820187e+09 | ... K14: =K12*K13 -> 2.8359313e+09
A16: Valor presente | B16: =SUM(B14:K14) -> 2.6880322e+10

Sheet Costos hundidos
B2: Estudio de mercado | C2: 5000 | D2: millones (COP)
B3: Estudios técnicos | C3: 2500 | D3: millones (COP)
B4: Avalúo comercial | C4: 420 | D4: millones (COP)
B6: Total | C6: =SUM(C2:C4) -> 7920 | D6: millones (COP)

Sheet Tasas de banco
E2: Datos | F2: Fuente
A3: Banco de Bogotá | D3: DTF TA | E3: 0.0848 | F3: https://www.grupoaval.com/wps/portal/grupo-aval/aval/portal-financiero/indicadores/tasas-interes
A4: Plazo 10 años | D4: Tasa TA | E4: 0.1898
A5: Tasa (DTF + 10.5% TA) | D5: Período trimestre anticipado | E5: 0.0475
A6: Pago de interés trimestral | D6: Período trimestre vencido | E6: 0.0498
A7: Amortización | D7: Nominal anual trimestre vencido | E7: 0.1993
A8: 1 año de gracia para pago de capital | D8: Efectivo anual | E8: 0.2147
A9: Amortizaciones de capitales anuales (10% a partir del año 2 y 20% al vencimiento)
A10: Gastos iniciales (6% sobre el valor del crédito descontado del valor desembolsado)
A12: Banco BBVA | E12: Datos | F12: Fuente
A13: Plazo 10 años | D13: IBR | E13: 0.10516 | F13: https://www.banrep.gov.co/es/glosario/indicador-bancario-referencia-ibr
A14: Tasa (IBR + 10.5% TV) | D14: Tasa TV (IBR + 10,5%) | E14: =+E13+10.5% -> 0.21016
A15: Pago de intereses trimestral | D15: Período trimestre vencido | E15: =+E14/4 -> 0.05254
A16: Pago: cuota fija (2 años de gracia de pago de capital) | D16: Nominal anual trimestre vencido | E16: =+E13+10.5% -> 0.21016
A17: Gastos iniciales (5.5% sobre el valor del crédito descontado del valor desembolsado) | D17: Efectivo anual | E17: =(1+E15)^4-1 -> 0.22731047
A19: Emisión de bonos corporativos
A20: Plazo 10 años
A21: Tasa: IPC + 10.5 E.A.
A22: Pago intereses: semestral
A23: Pago de capital: al vencimiento (bullet)
A24: Gastos emisión y estructuración (25% sobre el valor de emisión)
A26: ESTRUCTURA DE CAPITAL BASE
A27: Concepto | B27: Valor
A28: Inversión Total | B28: =+Datos!C10+Datos!C15 -> 21920
A29: % Deuda | B29: 0.1
A30: Valor Crédito | B30: =+B28*B29 -> 2192
A32: Concepto | B32: Banco Bogotá | C32: BBVA | D32: Bonos
A33: Plazo (años) | B33: 10 | C33: 10 | D33: 10
A34: Tasa base | B34: DTF+10.5% | C34: IBR+10.5% | D34: IPC+10.5%
A35: EA equivalente | B35: =+E8 -> 0.2147 | C35: =+E17 -> 0.22731047 | D35: X
A36: Pago intereses | B36: Trimestral | C36: Trimestral | D36: Semestral
A37: Gracia capital | B37: 1 año | C37: 2 años | D37: No aplica
A38: Forma pago capital | B38: Amortización | C38: Cuota fija | D38: Bullet
A39: Gastos iniciales | B39: 0.06 | C39: 5,5% | D39: 0.25
A40: Desembolso neto
A41: Intereses totales
A42: Costo efectivo
A44: BANCO DE BOGOTA
A45: Período | B45: Fecha | C45: Saldo Inicial | D45: Interés | E45: Capital | F45: Cuota | G45: Saldo Final
A46: 0 | B46: 46023 | C46: =+B30 -> 2192 | E46: =+IF(OR(A46=8,A46=12,A46=16,A46=20,A46=24,A46=28,A46=32,A46=36),14000000,IF(A46=40,14000000,0)) -> 0 | F46: =+D46+E46 -> 0 | G46: =+C46 -> 2192
...

Sheet Inflación
A1: Proyección de Inflación Colombia a 10 Años (2026-2035)
A3: Párametro | B3: Fecha | C3: Fuente
A4: Tes TF | B4: 46188 | C4: https://www.grupoaval.com/wps/portal/grupo-aval/aval/portal-financiero/renta-fija/tes/curva-rentabilidad
A5: Tes UVR | B5: 46188 | C5: 1. https://www.grupoaval.com/wps/portal/grupo-aval/aval/portal-financiero/renta-fija/tes/datos-historicos
C6: 2. https://www.bvc.com.co/renta-fija-deuda-publica-segmento-publico/tuvt11170327?tab=resumen
C7: 3. https://www.irc.gov.co/440
A10: Año | B10: Tes TF | C10: Tes UVR | D10: Inflación proyectada
A11: 2026 | D11: 0.0584
A12: 2027 | B12: 0.1303 | C12: 0.0619 | D12: =B12-C12 -> 0.0684
A13: 2028 | B13: 0.1299 | C13: =AVERAGE(C12,C14) -> 0.0641 | D13: =B13-C13 -> 0.0658
A14: 2029 | B14: 0.13 | C14: 0.0663 | D14: =B14-C14 -> 0.0637
A15: 2030 | B15: 0.1299 | C15: =AVERAGE(C14,C16) -> 0.06815 | D15: =B15-C15 -> 0.06175
A16: 2031 | B16: 0.1285 | C16: 0.07 | D16: =B16-C16 -> 0.0585
A17: 2032 | B17: 0.1265 | C17: =AVERAGE(C16,C18) -> 0.06835 | D17: =B17-C17 -> 0.05815
A18: 2033 | B18: 0.1255 | C18: 0.0667 | D18: =B18-C18 -> 0.0588
A19: 2034 | B19: 0.1247 | C19: =AVERAGE(C18,C20) -> 0.0661 | D19: =B19-C19 -> 0.0586
A20: 2035 | B20: 0.124 | C20: 0.0655 | D20: =B20-C20 -> 0.0585
A22: Nota: para el año 2026 se trabaja con la inflación reportada en mayo del 2026, para los años 2028, 2030, 2032 y 2034
A23: se hace una interpolación simple con respecto al año anterior y siguiente.
A34: Fuente: https://www.irc.gov.co/440

Sheet Bancos
A1: TABLA DE AMORTIZACIÓN - BANCO DE BOGOTÁ | P1: TABLA DE AMORTIZACIÓN - BANCO BBVA
A3: PARÁMETROS DEL PRÉSTAMO | D3: NOTAS: | P3: PARÁMETROS DEL PRÉSTAMO | S3: NOTAS:
A4: DTF (T.A.) - Vigente Jun 2026 | B4: 0.0936 | D4: DTF vigente 8-14 Jun 2026: 9.36% T.A. (Fuente: Banco de la República) | P4: IBR (T.V.) - Vigente Jun 2026 | Q4: 0.09 | S4: IBR vigente (~9.0% T.V.) | AF4: Plazo | AG4: 10 años
A5: Spread Banco Bogotá (T.A.) | B5: 0.105 | D5: Tasa Anticipada (TA) convertida a Vencida para cálculo de intereses | P5: Spread Banco BBVA (T.V.) | Q5: 0.105 | S5: Spread 10.5% Tasa Vencida | AF5: Tasa | AG5: IPC + 10,5% E.A.
A6: Tasa Total (T.A.) | B6: =B4+B5 -> 0.1986 | D6: Año 1: Período de gracia para capital (solo se pagan intereses) | P6: Tasa Total (T.V.) | Q6: =Q4+Q5 -> 0.195 | S6: IBR + Spread = Tasa nominal anual vencida | AF6: Spread | AG6: 0.105
A7: Tasa Trimestral Anticipada | B7: =(B6/4) -> 0.04965 | D7: Años 2-9: Amortización 10% anual del capital (2.5% trimestral) | P7: n1 | Q7: =360/92 -> 3.9130435 | AF7: IPC | AG7: 0.064
A8: Tasa Trimestral Vencido | B8: =B7/(1-B7) -> 0.05224391 | D8: Año 10: Amortización 20% anual del capital (5% trimestral) | P8: n2 | Q8: =365/92 -> 3.9673913 | AF8: Tasa Efectiva Anual | AG8: =AG6+AG7 -> 0.169
A9: Nominal Anual Trimestre Vencido | B9: =B8*4 -> 0.20897564 | D9: https://suameca.banrep.gov.co/indicadores-economicos-del-dia/ | P9: Tasa Trimestral Efectiva | Q9: =Q6/Q7 -> 0.049833333 | S9: Tasa trimestral para cálculo de intereses | AF9: Tasa Efectivo Semestral | AG9: =(1+AG8)^(6/12)-1 -> 0.081203034
A10: Efectivo Anual | B10: =(1+B9/4)^4-1 -> 0.22593003 | P10: Tasa Efectiva Anual | Q10: =(1+Q9)^Q8-1 -> 0.21280988 | S10: TEA calculada | AF10: Monto del Crédito (asumido) | AG10: =+B12 -> 8400
A11: Plazo (años) | B11: 10 | P11: Plazo (años) | Q11: 10 | S11: 10 años plazo total | AF11: Gastos (porcentaje) | AG11: 0.25
A12: Monto del Crédito (asumido) | B12: =Datos!C10*Datos!C35 -> 8400 | P12: Monto del Crédito | Q12: =+B12 -> 8400 | S12: Vinculado al monto de bogota | AF12: Gastos | AG12: =AG10*AG11 -> 2100
A13: Gastos Iniciales (%) | B13: 0.06 | P13: Gastos Iniciales (%) | Q13: 0.055 | S13: 5.5% sobre el valor del crédito | AF13: Intereses | AG13: =AG9*AG10 -> 682.10548 | AM13: RESUMEN ANUAL
A14: Valor Gastos Iniciales | B14: =B12*B13 -> 504 | P14: Valor Gastos Iniciales | Q14: =Q12*Q13 -> 462 | S14: Descontado del desembolso
A15: Monto Neto Desembolsado | B15: =B12-B14 -> 7896 | P15: Monto Neto Desembolsado | Q15: =Q12-Q14 -> 7938 | AM15: Año | AN15: Cupones | AO15: Amort. Principal | AP15: Pago Total | AQ15: Saldo Final
A16: Kd_DI | B16: =B10*(1-0.35) -> 0.14685452 | P16: Período de Gracia (años) | Q16: 2 | S16: Solo pago de intereses años 1-2 | AM16: 1 | AN16: =SUMIF($AG$20:$AG$39,AM16,$AI$20:$AI$39) -> 1364.211 | AO16: =SUMIF($AG$20:$AG$39,AM16,$AJ$20:$AJ$39) -> 0 | AP16: =+AN16+AO16 -> 1364.211
A17: TABLA DE AMORTIZACIÓN TRIMESTRAL | I17: RESUMEN ANUAL | P17: Cuota Fija Trimestral (Años 3-10) | Q17: =PMT(Q9,32,-Q12) -> 530.50126 | S17: Cuota fija para años 3-10 (32 trimestres) | AM17: 2 | AN17: =SUMIF($AG$20:$AG$39,AM17,$AI$20:$AI$39) -> 1364.211 | AO17: =SUMIF($AG$20:$AG$39,AM17,$AJ$20:$AJ$39) -> 0 | AP17: =+AN17+AO17 -> 1364.211
AM18: 3 | AN18: =SUMIF($AG$20:$AG$39,AM18,$AI$20:$AI$39) -> 1364.211 | AO18: =SUMIF($AG$20:$AG$39,AM18,$AJ$20:$AJ$39) -> 0 | AP18: =+AN18+AO18 -> 1364.211
A19: Trimestre | B19: Año | C19: Saldo Inicial | D19: Interés Trimestral | E19: Amort. Capital | F19: Pago Total | G19: Saldo Final | I19: Año | J19: Intereses | K19: Amort. Capital | L19: Pago Total | M19: Saldo Final | P19: TABLA DE AMORTIZACIÓN TRIMESTRAL | X19: RESUMEN ANUAL | AF19: Semestre | AG19: Año | AH19: Capital | AI19: Cupón (Interés) | AJ19: Amortización | AK19: Flujo Total | AM19: 4 | AN19: =SUMIF($AG$20:$AG$39,AM19,$AI$20:$AI$39) -> 1364.211 | AO19: =SUMIF($AG$20:$AG$39,AM19,$AJ$20:$AJ$39) -> 0 | AP19: =+AN19+AO19 -> 1364.211
A20: 1 | B20: 1 | C20: =$B$12 -> 8400 | D20: =C20*$B$8 -> 438.84885 | E20: =IF(B20=1,0,IF(B20<10,$B$12*0.1/4,$B$12*0.2/4)) -> 0 | F20: =D20+E20 -> 438.84885 | G20: =C20-E20 -> 8400 | I20: 1 | J20: =SUM(D20:D23) -> 1755.3954 | K20: =SUM(E20:E23) -> 0 | L20: =SUM(F20:F23) -> 1755.3954 | M20: =G23 -> 8400 | AF20: 1 | AG20: 1 | AH20: =+$AG$10 -> 8400 | AI20: =+$AG$13 -> 682.10548 | AJ20: 0 | AK20: =+AI20+AJ20 -> 682.10548 | AM20: 5 | AN20: =SUMIF($AG$20:$AG$39,AM20,$AI$20:$AI$39) -> 1364.211 | AO20: =SUMIF($AG$20:$AG$39,AM20,$AJ$20:$AJ$39) -> 0 | AP20: =+AN20+AO20 -> 1364.211
A21: 2 | B21: 1 | C21: =G20 -> 8400 | D21: =C21*$B$8 -> 438.84885 | E21: =IF(B21=1,0,IF(B21<10,$B$12*0.1/4,$B$12*0.2/4)) -> 0 | F21: =D21+E21 -> 438.84885 | G21: =C21-E21 -> 8400 | I21: 2 | J21: =SUM(D24:D27) -> 1689.5681 | K21: =SUM(E24:E27) -> 840 | L21: =SUM(F24:F27) -> 2529.5681 | M21: =G27 -> 7560 | P21: Trimestre | Q21: Año | R21: Saldo Inicial | S21: Interés Trimestral | T21: Amort. Capital | U21: Pago Total | V21: Saldo Final | X21: Año | Y21: Intereses | Z21: Amort. Capital | AA21: Pago Total | AB21: Saldo Final | AF21: 2 | AG21: 1 | AH21: =+$AG$10 -> 8400 | AI21: =+$AG$13 -> 682.10548 | AJ21: 0 | AK21: =+AI21+AJ21 -> 682.10548 | AM21: 6 | AN21: =SUMIF($AG$20:$AG$39,AM21,$AI$20:$AI$39) -> 1364.211 | AO21: =SUMIF($AG$20:$AG$39,AM21,$AJ$20:$AJ$39) -> 0 | AP21: =+AN21+AO21 -> 1364.211
A22: 3 | B22: 1 | C22: =G21 -> 8400 | D22: =C22*$B$8 -> 438.84885 | E22: =IF(B22=1,0,IF(B22<10,$B$12*0.1/4,$B$12*0.2/4)) -> 0 | F22: =D22+E22 -> 438.84885 | G22: =C22-E22 -> 8400 | I22: 3 | J22: =SUM(D28:D31) -> 1514.0285 | K22: =SUM(E28:E31) -> 840 | L22: =SUM(F28:F31) -> 2354.0285 | M22: =G31 -> 6720 | P22: 1 | Q22: =CEILING(P22/4,1) -> 1 | R22: =$B$12 -> 8400 | S22: =R22*$Q$9 -> 418.6 | T22: =IF(Q22<=$Q$16,0,$Q$17-S22) -> 0 | U22: =S22+T22 -> 418.6 | V22: =R22-T22 -> 8400 | X22: 1 | Y22: =SUMIF($B$22:$B$61,X22,$D$22:$D$61) -> 877.69769 | Z22: =SUMIF($B$22:$B$61,X22,$E$22:$E$61) -> 0 | AA22: =SUMIF($B$22:$B$61,X22,$F$22:$F$61) -> 877.69769 | AB22: {=INDEX($G$22:$G$61,X22*4)} -> 7980 | AF22: 3 | AG22: 2 | AH22: =+$AG$10 -> 8400 | AI22: =+$AG$13 -> 682.10548 | AJ22: 0 | AK22: =+AI22+AJ22 -> 682.10548 | AM22: 7 | AN22: =SUMIF($AG$20:$AG$39,AM22,$AI$20:$AI$39) -> 1364.211 | AO22: =SUMIF($AG$20:$AG$39,AM22,$AJ$20:$AJ$39) -> 0 | AP22: =+AN22+AO22 -> 1364.211
A23: 4 | B23: 1 | C23: =G22 -> 8400 | D23: =C23*$B$8 -> 438.84885 | E23: =IF(B23=1,0,IF(B23<10,$B$12*0.1/4,$B$12*0.2/4)) -> 0 | F23: =D23+E23 -> 438.84885 | G23: =C23-E23 -> 8400 | I23: 4 | J23: =SUM(D32:D35) -> 1338.489 | K23: =SUM(E32:E35) -> 840 | L23: =SUM(F32:F35) -> 2178.489 | M23: =G35 -> 5880 | P23: 2 | Q23: =CEILING(P23/4,1) -> 1 | R23: =V22 -> 8400 | S23: =R23*$Q$9 -> 418.6 | T23: =IF(Q23<=$Q$16,0,$Q$17-S23) -> 0 | U23: =S23+T23 -> 418.6 | V23: =R23-T23 -> 8400 | X23: 2 | Y23: =SUMIF($B$22:$B$61,X23,$D$22:$D$61) -> 1689.5681 | Z23: =SUMIF($B$22:$B$61,X23,$E$22:$E$61) -> 840 | AA23: =SUMIF($B$22:$B$61,X23,$F$22:$F$61) -> 2529.5681 | AB23: {=INDEX($G$22:$G$61,X23*4)} -> 7140 | AF23: 4 | AG23: 2 | AH23: =+$AG$10 -> 8400 | AI23: =+$AG$13 -> 682.10548 | AJ23: 0 | AK23: =+AI23+AJ23 -> 682.10548 | AM23: 8 | AN23: =SUMIF($AG$20:$AG$39,AM23,$AI$20:$AI$39) -> 1364.211 | AO23: =SUMIF($AG$20:$AG$39,AM23,$AJ$20:$AJ$39) -> 0 | AP23: =+AN23+AO23 -> 1364.211
A24: 5 | B24: 2 | C24: =G23 -> 8400 | D24: =C24*$B$8 -> 438.84885 | E24: =IF(B24=1,0,IF(B24<10,$B$12*0.1/4,$B$12*0.2/4)) -> 210 | F24: =D24+E24 -> 648.84885 | G24: =C24-E24 -> 8190 | I24: 5 | J24: =SUM(D36:D39) -> 1162.9494 | K24: =SUM(E36:E39) -> 840 | L24: =SUM(F36:F39) -> 2002.9494 | M24: =G39 -> 5040 | P24: 3 | Q24: =CEILING(P24/4,1) -> 1 | R24: =V23 -> 8400 | S24: =R24*$Q$9 -> 418.6 | T24: =IF(Q24<=$Q$16,0,$Q$17-S24) -> 0 | U24: =S24+T24 -> 418.6 | V24: =R24-T24 -> 8400 | X24: 3 | Y24: =SUMIF($B$22:$B$61,X24,$D$22:$D$61) -> 1514.0285 | Z24: =SUMIF($B$22:$B$61,X24,$E$22:$E$61) -> 840 | AA24: =SUMIF($B$22:$B$61,X24,$F$22:$F$61) -> 2354.0285 | AB24: {=INDEX($G$22:$G$61,X24*4)} -> 6300 | AF24: 5 | AG24: 3 | AH24: =+$AG$10 -> 8400 | AI24: =+$AG$13 -> 682.10548 | AJ24: 0 | AK24: =+AI24+AJ24 -> 682.10548 | AM24: 9 | AN24: =SUMIF($AG$20:$AG$39,AM24,$AI$20:$AI$39) -> 1364.211 | AO24: =SUMIF($AG$20:$AG$39,AM24,$AJ$20:$AJ$39) -> 0 | AP24: =+AN24+AO24 -> 1364.211
A25: 6 | B25: 2 | C25: =G24 -> 8190 | D25: =C25*$B$8 -> 427.87762 | E25: =IF(B25=1,0,IF(B25<10,$B$12*0.1/4,$B$12*0.2/4)) -> 210 | F25: =D25+E25 -> 637.87762 | G25: =C25-E25 -> 7980 | I25: 6 | J25: =SUM(D40:D43) -> 987.4099 | K25: =SUM(E40:E43) -> 840 | L25: =SUM(F40:F43) -> 1827.4099 | M25: =G43 -> 4200 | P25: 4 | Q25: =CEILING(P25/4,1) -> 1 | R25: =V24 -> 8400 | S25: =R25*$Q$9 -> 418.6 | T25: =IF(Q25<=$Q$16,0,$Q$17-S25) -> 0 | U25: =S25+T25 -> 418.6 | V25: =R25-T25 -> 8400 | X25: 4 | Y25: =SUMIF($B$22:$B$61,X25,$D$22:$D$61) -> 1338.489 | Z25: =SUMIF($B$22:$B$61,X25,$E$22:$E$61) -> 840 | AA25: =SUMIF($B$22:$B$61,X25,$F$22:$F$61) -> 2178.489 | AB25: {=INDEX($G$22:$G$61,X25*4)} -> 5460 | AF25: 6 | AG25: 3 | AH25: =+$AG$10 -> 8400 | AI25: =+$AG$13 -> 682.10548 | AJ25: 0 | AK25: =+AI25+AJ25 -> 682.10548 | AM25: 10 | AN25: =SUMIF($AG$20:$AG$39,AM25,$AI$20:$AI$39) -> 1364.211 | AO25: =SUMIF($AG$20:$AG$39,AM25,$AJ$20:$AJ$39) -> 8400 | AP25: =+AN25+AO25 -> 9764.211
A26: 7 | B26: 2 | C26: =G25 -> 7980 | D26: =C26*$B$8 -> 416.9064 | E26: =IF(B26=1,0,IF(B26<10,$B$12*0.1/4,$B$12*0.2/4)) -> 210 | F26: =D26+E26 -> 626.9064 | G26: =C26-E26 -> 7770 | I26: 7 | J26: =SUM(D44:D47) -> 811.87036 | K26: =SUM(E44:E47) -> 840 | L26: =SUM(F44:F47) -> 1651.8704 | M26: =G47 -> 3360 | P26: 5 | Q26: =CEILING(P26/4,1) -> 2 | R26: =V25 -> 8400 | S26: =R26*$Q$9 -> 418.6 | T26: =IF(Q26<=$Q$16,0,$Q$17-S26) -> 0 | U26: =S26+T26 -> 418.6 | V26: =R26-T26 -> 8400 | X26: 5 | Y26: =SUMIF($B$22:$B$61,X26,$D$22:$D$61) -> 1162.9494 | Z26: =SUMIF($B$22:$B$61,X26,$E$22:$E$61) -> 840 | AA26: =SUMIF($B$22:$B$61,X26,$F$22:$F$61) -> 2002.9494 | AB26: {=INDEX($G$22:$G$61,X26*4)} -> 4620 | AF26: 7 | AG26: 4 | AH26: =+$AG$10 -> 8400 | AI26: =+$AG$13 -> 682.10548 | AJ26: 0 | AK26: =+AI26+AJ26 -> 682.10548 | AM26: TOTAL | AN26: =SUM(AN16:AN25) -> 13642.11 | AO26: =SUM(AO16:AO25) -> 8400 | AP26: =SUM(AP16:AP25) -> 22042.11
A27: 8 | B27: 2 | C27: =G26 -> 7770 | D27: =C27*$B$8 -> 405.93518 | E27: =IF(B27=1,0,IF(B27<10,$B$12*0.1/4,$B$12*0.2/4)) -> 210 | F27: =D27+E27 -> 615.93518 | G27: =C27-E27 -> 7560 | I27: 8 | J27: =SUM(D48:D51) -> 636.33083 | K27: =SUM(E48:E51) -> 840 | L27: =SUM(F48:F51) -> 1476.3308 | M27: =G51 -> 2520 | P27: 6 | Q27: =CEILING(P27/4,1) -> 2 | R27: =V26 -> 8400 | S27: =R27*$Q$9 -> 418.6 | T27: =IF(Q27<=$Q$16,0,$Q$17-S27) -> 0 | U27: =S27+T27 -> 418.6 | V27: =R27-T27 -> 8400 | X27: 6 | Y27: =SUMIF($B$22:$B$61,X27,$D$22:$D$61) -> 987.4099 | Z27: =SUMIF($B$22:$B$61,X27,$E$22:$E$61) -> 840 | AA27: =SUMIF($B$22:$B$61,X27,$F$22:$F$61) -> 1827.4099 | AB27: {=INDEX($G$22:$G$61,X27*4)} -> 3780 | AF27: 8 | AG27: 4 | AH27: =+$AG$10 -> 8400 | AI27: =+$AG$13 -> 682.10548 | AJ27: 0 | AK27: =+AI27+AJ27 -> 682.10548
A28: 9 | B28: 3 | C28: =G27 -> 7560 | D28: =C28*$B$8 -> 394.96396 | E28: =IF(B28=1,0,IF(B28<10,$B$12*0.1/4,$B$12*0.2/4)) -> 210 | F28: =D28+E28 -> 604.96396 | G28: =C28-E28 -> 7350 | I28: 9 | J28: =SUM(D52:D55) -> 460.79129 | K28: =SUM(E52:E55) -> 840 | L28: =SUM(F52:F55) -> 1300.7913 | M28: =G55 -> 1680 | P28: 7 | Q28: =CEILING(P28/4,1) -> 2 | R28: =V27 -> 8400 | S28: =R28*$Q$9 -> 418.6 | T28: =IF(Q28<=$Q$16,0,$Q$17-S28) -> 0 | U28: =S28+T28 -> 418.6 | V28: =R28-T28 -> 8400 | X28: 7 | Y28: =SUMIF($B$22:$B$61,X28,$D$22:$D$61) -> 811.87036 | Z28: =SUMIF($B$22:$B$61,X28,$E$22:$E$61) -> 840 | AA28: =SUMIF($B$22:$B$61,X28,$F$22:$F$61) -> 1651.8704 | AB28: {=INDEX($G$22:$G$61,X28*4)} -> 2940 | AF28: 9 | AG28: 5 | AH28: =+$AG$10 -> 8400 | AI28: =+$AG$13 -> 682.10548 | AJ28: 0 | AK28: =+AI28+AJ28 -> 682.10548
A29: 10 | B29: 3 | C29: =G28 -> 7350 | D29: =C29*$B$8 -> 383.99274 | E29: =IF(B29=1,0,IF(B29<10,$B$12*0.1/4,$B$12*0.2/4)) -> 210 | F29: =D29+E29 -> 593.99274 | G29: =C29-E29 -> 7140 | I29: 10 | J29: =SUM(D56:D59) -> 219.42442 | K29: =SUM(E56:E59) -> 1680 | L29: =SUM(F56:F59) -> 1899.4244 | M29: =G59 -> 0 | P29: 8 | Q29: =CEILING(P29/4,1) -> 2 | R29: =V28 -> 8400 | S29: =R29*$Q$9 -> 418.6 | T29: =IF(Q29<=$Q$16,0,$Q$17-S29) -> 0 | U29: =S29+T29 -> 418.6 | V29: =R29-T29 -> 8400 | X29: 8 | Y29: =SUMIF($B$22:$B$61,X29,$D$22:$D$61) -> 636.33083 | Z29: =SUMIF($B$22:$B$61,X29,$E$22:$E$61) -> 840 | AA29: =SUMIF($B$22:$B$61,X29,$F$22:$F$61) -> 1476.3308 | AB29: {=INDEX($G$22:$G$61,X29*4)} -> 2100 | AF29: 10 | AG29: 5 | AH29: =+$AG$10 -> 8400 | AI29: =+$AG$13 -> 682.10548 | AJ29: 0 | AK29: =+AI29+AJ29 -> 682.10548
A30: 11 | B30: 3 | C30: =G29 -> 7140 | D30: =C30*$B$8 -> 373.02152 | E30: =IF(B30=1,0,IF(B30<10,$B$12*0.1/4,$B$12*0.2/4)) -> 210 | F30: =D30+E30 -> 583.02152 | G30: =C30-E30 -> 6930 | I30: TOTAL | J30: =SUM(J20:J29) -> 10576.257 | K30: =SUM(K20:K29) -> 8400 | L30: =SUM(L20:L29) -> 18976.257 | P30: 9 | Q30: =CEILING(P30/4,1) -> 3 | R30: =V29 -> 8400 | S30: =R30*$Q$9 -> 418.6 | T30: =IF(Q30<=$Q$16,0,$Q$17-S30) -> 111.90126 | U30: =S30+T30 -> 530.50126 | V30: =R30-T30 -> 8288.0987 | X30: 9 | Y30: =SUMIF($B$22:$B$61,X30,$D$22:$D$61) -> 460.79129 | Z30: =SUMIF($B$22:$B$61,X30,$E$22:$E$61) -> 840 | AA30: =SUMIF($B$22:$B$61,X30,$F$22:$F$61) -> 1300.7913 | AB30: {=INDEX($G$22:$G$61,X30*4)} -> 840 | AF30: 11 | AG30: 6 | AH30: =+$AG$10 -> 8400 | AI30: =+$AG$13 -> 682.10548 | AJ30: 0 | AK30: =+AI30+AJ30 -> 682.10548
A31: 12 | B31: 3 | C31: =G30 -> 6930 | D31: =C31*$B$8 -> 362.0503 | E31: =IF(B31=1,0,IF(B31<10,$B$12*0.1/4,$B$12*0.2/4)) -> 210 | F31: =D31+E31 -> 572.0503 | G31: =C31-E31 -> 6720 | P31: 10 | Q31: =CEILING(P31/4,1) -> 3 | R31: =V30 -> 8288.0987 | S31: =R31*$Q$9 -> 413.02359 | T31: =IF(Q31<=$Q$16,0,$Q$17-S31) -> 117.47767 | U31: =S31+T31 -> 530.50126 | V31: =R31-T31 -> 8170.6211 | X31: 10 | Y31: =SUMIF($B$22:$B$61,X31,$D$22:$D$61) -> 219.42442 | Z31: =SUMIF($B$22:$B$61,X31,$E$22:$E$61) -> 1680 | AA31: =SUMIF($B$22:$B$61,X31,$F$22:$F$61) -> 1899.4244 | AB31: {=INDEX($G$22:$G$61,X31*4)} -> 0 | AF31: 12 | AG31: 6 | AH31: =+$AG$10 -> 8400 | AI31: =+$AG$13 -> 682.10548 | AJ31: 0 | AK31: =+AI31+AJ31 -> 682.10548
A32: 13 | B32: 4 | C32: =G31 -> 6720 | D32: =C32*$B$8 -> 351.07908 | E32: =IF(B32=1,0,IF(B32<10,$B$12*0.1/4,$B$12*0.2/4)) -> 210 | F32: =D32+E32 -> 561.07908 | G32: =C32-E32 -> 6510 | I32: ESQUEMA DE AMORTIZACIÓN DE CAPITAL | P32: 11 | Q32: =CEILING(P32/4,1) -> 3 | R32: =V31 -> 8170.6211 | S32: =R32*$Q$9 -> 407.16928 | T32: =IF(Q32<=$Q$16,0,$Q$17-S32) -> 123.33197 | U32: =S32+T32 -> 530.50126 | V32: =R32-T32 -> 8047.2891 | X32: TOTAL | Y32: =SUM(Y22:Y31) -> 9698.5595 | Z32: =SUM(Z22:Z31) -> 8400 | AA32: =SUM(AA22:AA31) -> 18098.559 | AF32: 13 | AG32: 7 | AH32: =+$AG$10 -> 8400 | AI32: =+$AG$13 -> 682.10548 | AJ32: 0 | AK32: =+AI32+AJ32 -> 682.10548
A33: 14 | B33: 4 | C33: =G32 -> 6510 | D33: =C33*$B$8 -> 340.10786 | E33: =IF(B33=1,0,IF(B33<10,$B$12*0.1/4,$B$12*0.2/4)) -> 210 | F33: =D33+E33 -> 550.10786 | G33: =C33-E33 -> 6300 | I33: Año | J33: % Capital | K33: Monto Amort. | L33: Descripción | P33: 12 | Q33: =CEILING(P33/4,1) -> 3 | R33: =V32 -> 8047.2891 | S33: =R33*$Q$9 -> 401.02324 | T33: =IF(Q33<=$Q$16,0,$Q$17-S33) -> 129.47802 | U33: =S33+T33 -> 530.50126 | V33: =R33-T33 -> 7917.8111 | AF33: 14 | AG33: 7 | AH33: =+$AG$10 -> 8400 | AI33: =+$AG$13 -> 682.10548 | AJ33: 0 | AK33: =+AI33+AJ33 -> 682.10548
A34: 15 | B34: 4 | C34: =G33 -> 6300 | D34: =C34*$B$8 -> 329.13663 | E34: =IF(B34=1,0,IF(B34<10,$B$12*0.1/4,$B$12*0.2/4)) -> 210 | F34: =D34+E34 -> 539.13663 | G34: =C34-E34 -> 6090 | I34: 1 | J34: 0 | K34: =B12*0 -> 0 | L34: Período de gracia | P34: 13 | Q34: =CEILING(P34/4,1) -> 4 | R34: =V33 -> 7917.8111 | S34: =R34*$Q$9 -> 394.57092 | T34: =IF(Q34<=$Q$16,0,$Q$17-S34) -> 135.93034 | U34: =S34+T34 -> 530.50126 | V34: =R34-T34 -> 7781.8807 | AF34: 15 | AG34: 8 | AH34: =+$AG$10 -> 8400 | AI34: =+$AG$13 -> 682.10548 | AJ34: 0 | AK34: =+AI34+AJ34 -> 682.10548
A35: 16 | B35: 4 | C35: =G34 -> 6090 | D35: =C35*$B$8 -> 318.16541 | E35: =IF(B35=1,0,IF(B35<10,$B$12*0.1/4,$B$12*0.2/4)) -> 210 | F35: =D35+E35 -> 528.16541 | G35: =C35-E35 -> 5880 | I35: 2 | J35: 0.1 | K35: =B12*0.1 -> 840 | L35: Amortización regular | P35: 14 | Q35: =CEILING(P35/4,1) -> 4 | R35: =V34 -> 7781.8807 | S35: =R35*$Q$9 -> 387.79706 | T35: =IF(Q35<=$Q$16,0,$Q$17-S35) -> 142.7042 | U35: =S35+T35 -> 530.50126 | V35: =R35-T35 -> 7639.1766 | AF35: 16 | AG35: 8 | AH35: =+$AG$10 -> 8400 | AI35: =+$AG$13 -> 682.10548 | AJ35: 0 | AK35: =+AI35+AJ35 -> 682.10548
A36: 17 | B36: 5 | C36: =G35 -> 5880 | D36: =C36*$B$8 -> 307.19419 | E36: =IF(B36=1,0,IF(B36<10,$B$12*0.1/4,$B$12*0.2/4)) -> 210 | F36: =D36+E36 -> 517.19419 | G36: =C36-E36 -> 5670 | I36: 3 | J36: 0.1 | K36: =B12*0.1 -> 840 | L36: Amortización regular | P36: 15 | Q36: =CEILING(P36/4,1) -> 4 | R36: =V35 -> 7639.1766 | S36: =R36*$Q$9 -> 380.68563 | T36: =IF(Q36<=$Q$16,0,$Q$17-S36) -> 149.81562 | U36: =S36+T36 -> 530.50126 | V36: =R36-T36 -> 7489.3609 | AF36: 17 | AG36: 9 | AH36: =+$AG$10 -> 8400 | AI36: =+$AG$13 -> 682.10548 | AJ36: 0 | AK36: =+AI36+AJ36 -> 682.10548
A37: 18 | B37: 5 | C37: =G36 -> 5670 | D37: =C37*$B$8 -> 296.22297 | E37: =IF(B37=1,0,IF(B37<10,$B$12*0.1/4,$B$12*0.2/4)) -> 210 | F37: =D37+E37 -> 506.22297 | G37: =C37-E37 -> 5460 | I37: 4 | J37: 0.1 | K37: =B12*0.1 -> 840 | L37: Amortización regular | P37: 16 | Q37: =CEILING(P37/4,1) -> 4 | R37: =V36 -> 7489.3609 | S37: =R37*$Q$9 -> 373.21982 | T37: =IF(Q37<=$Q$16,0,$Q$17-S37) -> 157.28144 | U37: =S37+T37 -> 530.50126 | V37: =R37-T37 -> 7332.0795 | AF37: 18 | AG37: 9 | AH37: =+$AG$10 -> 8400 | AI37: =+$AG$13 -> 682.10548 | AJ37: 0 | AK37: =+AI37+AJ37 -> 682.10548
A38: 19 | B38: 5 | C38: =G37 -> 5460 | D38: =C38*$B$8 -> 285.25175 | E38: =IF(B38=1,0,IF(B38<10,$B$12*0.1/4,$B$12*0.2/4)) -> 210 | F38: =D38+E38 -> 495.25175 | G38: =C38-E38 -> 5250 | I38: 5 | J38: 0.1 | K38: =B12*0.1 -> 840 | L38: Amortización regular | P38: 17 | Q38: =CEILING(P38/4,1) -> 5 | R38: =V37 -> 7332.0795 | S38: =R38*$Q$9 -> 365.38196 | T38: =IF(Q38<=$Q$16,0,$Q$17-S38) -> 165.11929 | U38: =S38+T38 -> 530.50126 | V38: =R38-T38 -> 7166.9602 | AF38: 19 | AG38: 10 | AH38: =+$AG$10 -> 8400 | AI38: =+$AG$13 -> 682.10548 | AJ38: 0 | AK38: =+AI38+AJ38 -> 682.10548
A39: 20 | B39: 5 | C39: =G38 -> 5250 | D39: =C39*$B$8 -> 274.28053 | E39: =IF(B39=1,0,IF(B39<10,$B$12*0.1/4,$B$12*0.2/4)) -> 210 | F39: =D39+E39 -> 484.28053 | G39: =C39-E39 -> 5040 | I39: 6 | J39: 0.1 | K39: =B12*0.1 -> 840 | L39: Amortización regular | P39: 18 | Q39: =CEILING(P39/4,1) -> 5 | R39: =V38 -> 7166.9602 | S39: =R39*$Q$9 -> 357.15352 | T39: =IF(Q39<=$Q$16,0,$Q$17-S39) -> 173.34774 | U39: =S39+T39 -> 530.50126 | V39: =R39-T39 -> 6993.6125 | AF39: 20 | AG39: 10 | AH39: =+$AG$10 -> 8400 | AI39: =+$AG$13 -> 682.10548 | AJ39: =+AG10 -> 8400 | AK39: =+AI39+AJ39 -> 9082.1055
A40: 21 | B40: 6 | C40: =G39 -> 5040 | D40: =C40*$B$8 -> 263.30931 | E40: =IF(B40=1,0,IF(B40<10,$B$12*0.1/4,$B$12*0.2/4)) -> 210 | F40: =D40+E40 -> 473.30931 | G40: =C40-E40 -> 4830 | I40: 7 | J40: 0.1 | K40: =B12*0.1 -> 840 | L40: Amortización regular | P40: 19 | Q40: =CEILING(P40/4,1) -> 5 | R40: =V39 -> 6993.6125 | S40: =R40*$Q$9 -> 348.51502 | T40: =IF(Q40<=$Q$16,0,$Q$17-S40) -> 181.98624 | U40: =S40+T40 -> 530.50126 | V40: =R40-T40 -> 6811.6262 | AF40: TOTALES | AI40: =SUM(AI20:AI39) -> 13642.11 | AJ40: =SUM(AJ20:AJ39) -> 8400 | AK40: =SUM(AK20:AK39) -> 22042.11
A41: 22 | B41: 6 | C41: =G40 -> 4830 | D41: =C41*$B$8 -> 252.33809 | E41: =IF(B41=1,0,IF(B41<10,$B$12*0.1/4,$B$12*0.2/4)) -> 210 | F41: =D41+E41 -> 462.33809 | G41: =C41-E41 -> 4620 | I41: 8 | J41: 0.1 | K41: =B12*0.1 -> 840 | L41: Amortización regular | P41: 20 | Q41: =CEILING(P41/4,1) -> 5 | R41: =V40 -> 6811.6262 | S41: =R41*$Q$9 -> 339.44604 | T41: =IF(Q41<=$Q$16,0,$Q$17-S41) -> 191.05522 | U41: =S41+T41 -> 530.50126 | V41: =R41-T41 -> 6620.571
...

Sheet WACC
A1: Tasa libre de riesgo (Rf) | B1: 0.0444 | C1: https://www.bloomberg.com/markets/rates-bonds/government-bonds/us
A2: Retorno esperado del mercado | B2: 0.12591818
A3: Equity Risk Premium | B3: =B2-B1 -> 0.081518182
A4: Beta de la empresa apalancado (βL) | B4: 1.04 | C4: Metales y minería
A5: D/E sector | B5: 0.1098
A6: Tasa impositiva Colombia | B6: =Datos!C17 -> 0.35
A7: Beta de la empresa desapalancado (βU) | B7: =((B4)/(1+(1-B6)*B5)) -> 0.97071973 | C7: Calculado
A8: Beta del sector desapalancado (βU) | B8: 0.96 | C8: Damodaran, Metales y minería
A9: D/E ratio | B9: =Datos!C35/Datos!C34 -> 1.5 | C9: (10%D / 90%E)
A10: Beta reapalancado a la estructura del proyecto (βLproyecto) | B10: =B7*(1+(1-B6)*(B9)) -> 1.9171715 | C10: Calculado
A11: Bono Yankee_TES Globales de Colombia en USD a 10 años | B11: 0.06643 | C11: https://www.grupoaval.com/wps/portal/grupo-aval/aval/portal-financiero/renta-fija/yankees
A12: Riesgo país (Rp) | B12: =B11-B1 -> 0.02203 | C12: Calculado
A13: TES de Colombia en COP a 10 años | B13: 0.121 | C13: https://www.grupoaval.com/wps/portal/grupo-aval/aval/portal-financiero/renta-fija/tes/curva-rentabilidad
A14: Devaluación esperada | B14: =B13-B11 -> 0.05457 | C14: Calculado
A15: Ke_USD | B15: =B1+B10*B3+B12 -> 0.22271433
A16: Ke_COP | B16: =(1+B15)*(1+B14)-1 -> 0.28943785
A18: WACC | B18: =$B$16*Datos!$C$34+Datos!$C$35*Bancos!$B$10*(1-B6) -> 0.20388785

Sheet Depreciaciones
A1: Detalle | B1: Año 1 | C1: Año 2 | D1: Año 3 | E1: Año 4 | F1: Año 5 | G1: Año 6 | H1: Año 7 | I1: Año 8 | J1: Año 9 | K1: Año 10 | M1: Posible renovación total | N1: Página 5, nota 13
A2: Maquinaria y Equipos | B2: =Datos!$C$5*1000000/Datos!$E$5 -> 425000000 | C2: =Datos!$C$5*1000000/Datos!$E$5 -> 425000000 | D2: =Datos!$C$5*1000000/Datos!$E$5 -> 425000000 | E2: =Datos!$C$5*1000000/Datos!$E$5 -> 425000000 | F2: =Datos!$C$5*1000000/Datos!$E$5 -> 425000000 | G2: =Datos!$C$5*1000000/Datos!$E$5 -> 425000000 | H2: =Datos!$C$5*1000000/Datos!$E$5 -> 425000000 | I2: =Datos!$C$5*1000000/Datos!$E$5 -> 425000000 | ... K2: =Datos!$C$5*1000000/Datos!$E$5 -> 425000000 | M2: Sobre el activo fijo "maquina"
A3: Muebles y Enseres | B3: =Datos!$C$6*1000000/Datos!$E$6 -> 250000000 | C3: =Datos!$C$6*1000000/Datos!$E$6 -> 250000000 | D3: =Datos!$C$6*1000000/Datos!$E$6 -> 250000000 | E3: =Datos!$C$6*1000000/Datos!$E$6 -> 250000000 | F3: =Datos!$C$6*1000000/Datos!$E$6 -> 250000000 | G3: =Datos!$C$6*1000000/Datos!$E$6 -> 250000000 | H3: =Datos!$C$6*1000000/Datos!$E$6 -> 250000000 | I3: =Datos!$C$6*1000000/Datos!$E$6 -> 250000000 | ... K3: =Datos!$C$6*1000000/Datos!$E$6 -> 250000000 | M3: Genera nueva depreciacion desde el año 5
A4: Obras Civiles | B4: =Datos!$C$7*1000000/Datos!$E$7 -> 19800000 | C4: =Datos!$C$7*1000000/Datos!$E$7 -> 19800000 | D4: =Datos!$C$7*1000000/Datos!$E$7 -> 19800000 | E4: =Datos!$C$7*1000000/Datos!$E$7 -> 19800000 | F4: =Datos!$C$7*1000000/Datos!$E$7 -> 19800000 | G4: =Datos!$C$7*1000000/Datos!$E$7 -> 19800000 | H4: =Datos!$C$7*1000000/Datos!$E$7 -> 19800000 | I4: =Datos!$C$7*1000000/Datos!$E$7 -> 19800000 | ... K4: =Datos!$C$7*1000000/Datos!$E$7 -> 19800000
A5: Montaje | B5: =Datos!$C$8*1000000/Datos!$E$8 -> 42500000 | C5: =Datos!$C$8*1000000/Datos!$E$8 -> 42500000 | D5: =Datos!$C$8*1000000/Datos!$E$8 -> 42500000 | E5: =Datos!$C$8*1000000/Datos!$E$8 -> 42500000 | F5: =Datos!$C$8*1000000/Datos!$E$8 -> 42500000 | G5: =Datos!$C$8*1000000/Datos!$E$8 -> 42500000 | H5: =Datos!$C$8*1000000/Datos!$E$8 -> 42500000 | I5: =Datos!$C$8*1000000/Datos!$E$8 -> 42500000 | ... K5: =Datos!$C$8*1000000/Datos!$E$8 -> 42500000
A6: Transporte de Equipos | B6: =Datos!$C$9*1000000/Datos!$E$9 -> 62500000 | C6: =Datos!$C$9*1000000/Datos!$E$9 -> 62500000 | D6: =Datos!$C$9*1000000/Datos!$E$9 -> 62500000 | E6: =Datos!$C$9*1000000/Datos!$E$9 -> 62500000 | F6: =Datos!$C$9*1000000/Datos!$E$9 -> 62500000 | G6: =Datos!$C$9*1000000/Datos!$E$9 -> 62500000 | H6: =Datos!$C$9*1000000/Datos!$E$9 -> 62500000 | I6: =Datos!$C$9*1000000/Datos!$E$9 -> 62500000 | ... K6: =Datos!$C$9*1000000/Datos!$E$9 -> 62500000
A7: Total | B7: =SUM(B2:B6) -> 799800000 | C7: =SUM(C2:C6) -> 799800000 | D7: =SUM(D2:D6) -> 799800000 | E7: =SUM(E2:E6) -> 799800000 | F7: =SUM(F2:F6) -> 799800000 | G7: =SUM(G2:G6) -> 799800000 | H7: =SUM(H2:H6) -> 799800000 | I7: =SUM(I2:I6) -> 799800000 | ... K7: =SUM(K2:K6) -> 799800000

Sheet Amortización gasto seguro
A1: Detalle | B1: Año 1 | C1: Año 2 | D1: Año 3 | E1: Año 4 | F1: Año 5 | G1: Año 6 | H1: Año 7 | I1: Año 8 | J1: Año 9 | K1: Año 10
A2: Seguro en primeros 5 años | B2: =1000000*Datos!$C$10*Datos!$C$25/5 -> 280000000 | C2: =1000000*Datos!$C$10*Datos!$C$25/5 -> 280000000 | D2: =1000000*Datos!$C$10*Datos!$C$25/5 -> 280000000 | E2: =1000000*Datos!$C$10*Datos!$C$25/5 -> 280000000 | F2: =1000000*Datos!$C$10*Datos!$C$25/5 -> 280000000 | G2: 0 | H2: 0 | I2: 0 | J2: 0 | K2: 0
A3: Seguro en segundos 5 años | B3: 0 | C3: 0 | D3: 0 | E3: 0 | F3: 0 | G3: =1000000*Datos!$C$10*Datos!$C$25/5 -> 280000000 | H3: =1000000*Datos!$C$10*Datos!$C$25/5 -> 280000000 | I3: =1000000*Datos!$C$10*Datos!$C$25/5 -> 280000000 | J3: =1000000*Datos!$C$10*Datos!$C$25/5 -> 280000000 | K3: =1000000*Datos!$C$10*Datos!$C$25/5 -> 280000000
A4: Total | B4: =SUM(B2:B3) -> 280000000 | C4: =SUM(C2:C3) -> 280000000 | D4: =SUM(D2:D3) -> 280000000 | E4: =SUM(E2:E3) -> 280000000 | F4: =SUM(F2:F3) -> 280000000 | G4: =SUM(G2:G3) -> 280000000 | H4: =SUM(H2:H3) -> 280000000 | I4: =SUM(I2:I3) -> 280000000 | ... K4: =SUM(K2:K3) -> 280000000

Sheet Estado de resultados
B1: Año | C1: Año 0 | D1: Año 1 | E1: Año 2 | F1: Año 3 | G1: Año 4 | H1: Año 5 | I1: Año 6 | J1: Año 7 | K1: Año 8 | L1: Año 9 | M1: Año 10
B2: Consecutivo | C2: 0 | D2: 1 | E2: 2 | F2: 3 | G2: 4 | H2: 5 | I2: 6 | J2: 7 | K2: 8 | L2: 9 | M2: 10
B4: Inflación | D4: 0.0584 | E4: 0.0684 | F4: 0.0658 | G4: 0.0637 | H4: 0.06175 | I4: 0.0585 | J4: 0.05815 | K4: 0.0588 | L4: 0.0586 | M4: 0.0585
B5: Tasa de impuestos | D5: 0.35 | E5: 0.35 | F5: 0.35 | G5: 0.35 | H5: 0.35 | I5: 0.35 | J5: 0.35 | K5: 0.35 | L5: 0.35 | M5: 0.35
B8: Precio | D8: =6500000 -> 6500000 | E8: =D8*(1+D4)*(1+Datos!$C$31) -> 7292376 | F8: =E8*(1+E4)*(1+Datos!$C$31) -> 8258645 | G8: =F8*(1+F4)*(1+Datos!$C$31) -> 9330187.7 | H8: =G8*(1+G4)*(1+Datos!$C$31) -> 10519992 | I8: =H8*(1+H4)*(1+Datos!$C$31) -> 11839777 | J8: =I8*(1+I4)*(1+Datos!$C$31) -> 13284349 | K8: =J8*(1+J4)*(1+Datos!$C$31) -> 14900244 | L8: =K8*(1+K4)*(1+Datos!$C$31) -> 16722961 | M8: =L8*(1+L4)*(1+Datos!$C$31) -> 18765102
B9: Costo | D9: =Datos!C22 -> 1600000 | E9: =D9*(1+D4)*(1+Datos!$C$23) -> 1727308.8 | F9: =E9*(1+E4)*(1+Datos!$C$23) -> 1882365.9 | G9: =F9*(1+F4)*(1+Datos!$C$23) -> 2046350 | H9: =G9*(1+G4)*(1+Datos!$C$23) -> 2220236.6 | I9: =H9*(1+H4)*(1+Datos!$C$23) -> 2404482.9 | J9: =I9*(1+I4)*(1+Datos!$C$23) -> 2596048.1 | K9: =J9*(1+J4)*(1+Datos!$C$23) -> 2801948.4 | L9: =K9*(1+K4)*(1+Datos!$C$23) -> 3026037.1 | M9: =L9*(1+L4)*(1+Datos!$C$23) -> 3267430.1
B10: Cantidades | D10: 1500 | E10: 5000 | F10: 5000 | G10: 5000 | H10: 5000 | I10: 5000 | J10: 5000 | K10: 5000 | L10: 5000 | M10: 5000
B14: ESTADO DE RESULTADOS | C14: Año 0 | D14: Año 1 | E14: Año 2 | F14: Año 3 | G14: Año 4 | H14: Año 5 | I14: Año 6 | J14: Año 7 | K14: Año 8 | L14: Año 9 | M14: Año 10 | N14: Año 11
A15: =D15/$D$15 -> 1 | B15: Ingresos operacionales | D15: =D8*D10 -> 9750000000 | E15: =E8*E10 -> 36461880000 | F15: =F8*F10 -> 4.1293225e+10 | G15: =G8*G10 -> 4.6650938e+10 | H15: =H8*H10 -> 5.2599959e+10 | I15: =I8*I10 -> 5.9198887e+10 | J15: =J8*J10 -> 6.6421743e+10 | K15: =K8*K10 -> 7.4501218e+10 | ... M15: =M8*M10 -> 9.3825508e+10
A16: =D16/$D$15 -> 0.24615385 | B16: Costo de ventas | D16: =D9*D10 -> 2400000000 | E16: =E9*E10 -> 8636544000 | F16: =F9*F10 -> 9.4118293e+09 | G16: =G9*G10 -> 1.023175e+10 | H16: =H9*H10 -> 1.1101183e+10 | I16: =I9*I10 -> 1.2022415e+10 | J16: =J9*J10 -> 1.298024e+10 | K16: =K9*K10 -> 1.4009742e+10 | ... M16: =M9*M10 -> 1.633715e+10
A17: =D17/D15 -> 0.030769231 | B17: Costo de nómina asociada a la operación | D17: =Nómina!H3 -> 300000000 | E17: =D17*(1+D4) -> 317520000 | F17: =E17*(1+E4) -> 339238368 | G17: =F17*(1+F4) -> 3.6156025e+08 | H17: =G17*(1+G4) -> 3.8459164e+08 | I17: =H17*(1+H4) -> 4.0834017e+08 | J17: =I17*(1+I4) -> 4.3222807e+08 | K17: =J17*(1+J4) -> 4.5736214e+08 | L17: =K17*(1+K4) -> 4.8425503e+08 | M17: =L17*(1+L4) -> 5.1263238e+08
A18: =D18/D15 -> 0.055 | B18: Costo de mantenimiento | D18: =D15*Datos!$C$21 -> 536250000 | E18: =E15*Datos!$C$21 -> 2005403400 | F18: =F15*Datos!$C$21 -> 2.2711274e+09 | G18: =G15*Datos!$C$21 -> 2.5658016e+09 | H18: =H15*Datos!$C$21 -> 2.8929978e+09 | I18: =I15*Datos!$C$21 -> 3.2559388e+09 | J18: =J15*Datos!$C$21 -> 3.6531959e+09 | K18: =K15*Datos!$C$21 -> 4.097567e+09 | ... M18: =M15*Datos!$C$21 -> 5.1604029e+09
A19: =D19/$D$15 -> 0.66807692 | B19: Utilidad bruta | D19: =D15-D16-D17-D18 -> 6513750000 | E19: =E15-E16-E17-E18 -> 25502412600 | F19: =F15-F16-F17-F18 -> 2.927103e+10 | G19: =G15-G16-G17-G18 -> 3.3491826e+10 | H19: =H15-H16-H17-H18 -> 3.8221187e+10 | I19: =I15-I16-I17-I18 -> 4.3512194e+10 | J19: =J15-J16-J17-J18 -> 4.9356079e+10 | K19: =K15-K16-K17-K18 -> 5.5936546e+10 | ... M19: =M15-M16-M17-M18 -> 7.1815322e+10
A20: =D20/$D$15 -> 0.15261538 | B20: Costos de nómina administrativos | D20: =Nómina!H4 -> 1488000000 | E20: =D20*(1+D4) -> 1574899200 | F20: =E20*(1+E4) -> 1.6826223e+09 | G20: =F20*(1+F4) -> 1.7933389e+09 | H20: =G20*(1+G4) -> 1.9075745e+09 | I20: =H20*(1+H4) -> 2.0253673e+09 | J20: =I20*(1+I4) -> 2.1438513e+09 | K20: =J20*(1+J4) -> 2.2685162e+09 | L20: =K20*(1+K4) -> 2.401905e+09 | M20: =L20*(1+L4) -> 2.5426566e+09
A21: =D21/$D$15 -> 0.25 | B21: Gastos operacionales (variable) | D21: =D15*Datos!$C$26 -> 2437500000 | E21: =E15*Datos!$C$26 -> 9115470000 | F21: =F15*Datos!$C$26 -> 1.0323306e+10 | G21: =G15*Datos!$C$26 -> 1.1662735e+10 | H21: =H15*Datos!$C$26 -> 1.314999e+10 | I21: =I15*Datos!$C$26 -> 1.4799722e+10 | J21: =J15*Datos!$C$26 -> 1.6605436e+10 | K21: =K15*Datos!$C$26 -> 1.8625304e+10 | ... M21: =M15*Datos!$C$26 -> 2.3456377e+10
A22: =D22/$D$15 -> 0.082030769 | B22: Depreciación | D22: {=Depreciaciones!B7:K7} -> 799800000 | E22: 799800000 | F22: 799800000 | G22: 799800000 | H22: 799800000 | I22: 799800000 | J22: 799800000 | K22: 799800000 | L22: 799800000 | M22: 799800000
A23: =D23/$D$15 -> 0 | B23: Amortización | D23: =0 -> 0 | E23: =0 -> 0 | F23: =0 -> 0 | G23: =0 -> 0 | H23: =0 -> 0 | I23: =0 -> 0 | J23: =0 -> 0 | K23: =0 -> 0 | ... M23: =0 -> 0
A24: =D24/$D$15 -> 0.02 | B24: Comisiones | D24: =D15*Datos!$C$27 -> 195000000 | E24: =E15*Datos!$C$27 -> 729237600 | F24: =F15*Datos!$C$27 -> 8.258645e+08 | G24: =G15*Datos!$C$27 -> 9.3301877e+08 | H24: =H15*Datos!$C$27 -> 1.0519992e+09 | I24: =I15*Datos!$C$27 -> 1.1839777e+09 | J24: =J15*Datos!$C$27 -> 1.3284349e+09 | K24: =K15*Datos!$C$27 -> 1.4900244e+09 | ... M24: =M15*Datos!$C$27 -> 1.8765102e+09
A25: =D25/$D$15 -> 0.028717949 | B25: Gastos por seguro | D25: {='Amortización gasto seguro'!B4:K4} -> 280000000 | E25: 280000000 | F25: 280000000 | G25: 280000000 | H25: 280000000 | I25: 280000000 | J25: 280000000 | K25: 280000000 | L25: 280000000 | M25: 280000000
A26: =D26/$D$15 -> 0.13471282 | B26: EBIT | D26: =D19-D20-D21-D22-D23-D24-D25 -> 1313450000 | E26: =E19-E20-E21-E22-E23-E24 -> 13283005800 | F26: =F19-F20-F21-F22-F23-F24 -> 1.5639437e+10 | G26: =G19-G20-G21-G22-G23-G24 -> 1.8302934e+10 | H26: =H19-H20-H21-H22-H23-H24 -> 2.1311823e+10 | I26: =I19-I20-I21-I22-I23-I24 -> 2.4703327e+10 | J26: =J19-J20-J21-J22-J23-J24 -> 2.8478557e+10 | K26: =K19-K20-K21-K22-K23-K24 -> 3.2752901e+10 | L26: =L19-L20-L21-L22-L23-L24 -> 3.7623847e+10 | M26: =M19-M20-M21-M22-M23-M24 -> 4.3139978e+10
A27: =D27/$D$15 -> 0.0090020276 | B27: Gastos financieros (intereses) | D27: {=TRANSPOSE(Bancos!Y22:Y31)*100000} -> 87769769 | E27: 1.6895681e+08 | F27: 1.5140285e+08 | G27: 1.338489e+08 | H27: 1.1629494e+08 | I27: 98740990 | J27: 81187036 | K27: 63633083 | L27: 46079129 | M27: 21942442
A28: =D28/$D$15 -> 0.12571079 | B28: EBT | D28: =D26-D27 -> 1.2256802e+09 | E28: =E26-E27 -> 1.3114049e+10 | F28: =F26-F27 -> 1.5488034e+10 | G28: =G26-G27 -> 1.8169085e+10 | H28: =H26-H27 -> 2.1195528e+10 | I28: =I26-I27 -> 2.4604586e+10 | J28: =J26-J27 -> 2.839737e+10 | K28: =K26-K27 -> 3.2689268e+10 | ... M28: =M26-M27 -> 4.3118036e+10
A29: =D29/$D$15 -> 0.043998778 | B29: Provisión de impuestos | D29: =IF(D28<0,0,D28*D5) -> 4.2898808e+08 | E29: =IF(E28<0,0,E28*E5) -> 4.5899171e+09 | F29: =IF(F28<0,0,F28*F5) -> 5.4208119e+09 | G29: =IF(G28<0,0,G28*G5) -> 6.3591798e+09 | H29: =IF(H28<0,0,H28*H5) -> 7.418435e+09 | I29: =IF(I28<0,0,I28*I5) -> 8.611605e+09 | J29: =IF(J28<0,0,J28*J5) -> 9.9390795e+09 | K29: =IF(K28<0,0,K28*K5) -> 1.1441244e+10 | ... M29: =IF(M28<0,0,M28*M5) -> 1.5091313e+10
A30: =D30/$D$15 -> 0.081712015 | B30: Utilidad neta | D30: =D28-D29 -> 7.9669215e+08 | E30: =E28-E29 -> 8.5241318e+09 | F30: =F28-F29 -> 1.0067222e+10 | G30: =G28-G29 -> 1.1809905e+10 | H30: =H28-H29 -> 1.3777093e+10 | I30: =I28-I29 -> 1.5992981e+10 | J30: =J28-J29 -> 1.8458291e+10 | K30: =K28-K29 -> 2.1248024e+10 | ... M30: =M28-M29 -> 2.8026723e+10
B32: EBITDA | D32: =D26+D22+D23 -> 2113250000 | E32: =E26+E22+E23 -> 14082805800 | F32: =F26+F22+F23 -> 1.6439237e+10 | G32: =G26+G22+G23 -> 1.9102734e+10 | H32: =H26+H22+H23 -> 2.2111623e+10 | I32: =I26+I22+I23 -> 2.5503127e+10 | J32: =J26+J22+J23 -> 2.9278357e+10 | K32: =K26+K22+K23 -> 3.3552701e+10 | ... M32: =M26+M22+M23 -> 4.3939778e+10
A34: =D34/$D$15 -> 0.083333333 | B34: CXC | D34: =(Datos!$C$28/360)*'Estado de resultados'!D15 -> 812500000 | E34: =(Datos!$C$28/360)*'Estado de resultados'!E15 -> 3038490000 | F34: =(Datos!$C$28/360)*'Estado de resultados'!F15 -> 3.4411021e+09 | G34: =(Datos!$C$28/360)*'Estado de resultados'!G15 -> 3.8875782e+09 | H34: =(Datos!$C$28/360)*'Estado de resultados'!H15 -> 4.3833299e+09 | I34: =(Datos!$C$28/360)*'Estado de resultados'!I15 -> 4.9332406e+09 | J34: =(Datos!$C$28/360)*'Estado de resultados'!J15 -> 5.5351453e+09 | K34: =(Datos!$C$28/360)*'Estado de resultados'!K15 -> 6.2084348e+09 | ... M34: =(Datos!$C$28/360)*'Estado de resultados'!M15 -> 7.8187923e+09
B35: KTO | D35: =D34 -> 812500000 | E35: =E34 -> 3038490000 | F35: =F34 -> 3.4411021e+09 | G35: =G34 -> 3.8875782e+09 | H35: =H34 -> 4.3833299e+09 | I35: =I34 -> 4.9332406e+09 | J35: =J34 -> 5.5351453e+09 | K35: =K34 -> 6.2084348e+09 | ... M35: =M34 -> 7.8187923e+09
A36: =D36/$D$15 -> 0.061538462 | B36: CXP | D36: =(Datos!$C$29/360)*'Estado de resultados'!D16 -> 600000000 | E36: =(Datos!$C$29/360)*'Estado de resultados'!E16 -> 2159136000 | F36: =(Datos!$C$29/360)*'Estado de resultados'!F16 -> 2.3529573e+09 | G36: =(Datos!$C$29/360)*'Estado de resultados'!G16 -> 2.5579376e+09 | H36: =(Datos!$C$29/360)*'Estado de resultados'!H16 -> 2.7752957e+09 | I36: =(Datos!$C$29/360)*'Estado de resultados'!I16 -> 3.0056037e+09 | J36: =(Datos!$C$29/360)*'Estado de resultados'!J16 -> 3.2450601e+09 | K36: =(Datos!$C$29/360)*'Estado de resultados'!K16 -> 3.5024355e+09 | ... M36: =(Datos!$C$29/360)*'Estado de resultados'!M16 -> 4.0842876e+09
A37: =D37/$D$15 -> 0.043998778 | B37: Impuestos por pagar | D37: =D29 -> 4.2898808e+08 | E37: =E29 -> 4.5899171e+09 | F37: =F29 -> 5.4208119e+09 | G37: =G29 -> 6.3591798e+09 | H37: =H29 -> 7.418435e+09 | I37: =I29 -> 8.611605e+09 | J37: =J29 -> 9.9390795e+09 | K37: =K29 -> 1.1441244e+10 | ... M37: =M29 -> 1.5091313e+10
B38: KTNO | D38: =D35-D36-D37 -> -2.1648808e+08 | E38: =E35-E36-E37 -> -3.7105631e+09 | F38: =F35-F36-F37 -> -4.3326672e+09 | G38: =G35-G36-G37 -> -5.0295392e+09 | H38: =H35-H36-H37 -> -5.8104007e+09 | I38: =I35-I36-I37 -> -6.6839681e+09 | J38: =J35-J36-J37 -> -7.6489943e+09 | K38: =K35-K36-K37 -> -8.7352447e+09 | ... M38: =M35-M36-M37 -> -1.1356808e+10 | O38: Proyección venta de activos | P38: 0.3
B39: Δ KTNO | D39: =D38 -> -2.1648808e+08 | E39: =E38-D38 -> -3.4940751e+09 | F39: =F38-E38 -> -6.22104e+08 | G39: =G38-F38 -> -6.9687201e+08 | H39: =H38-G38 -> -7.8086159e+08 | I39: =I38-H38 -> -8.7356733e+08 | J39: =J38-I38 -> -9.6502624e+08 | K39: =K38-J38 -> -1.0862503e+09 | L39: =L38-K38 -> -1.23162e+09 | M39: =M38-L38 -> -1.3899432e+09 | O39: Costo de desmantelamiento | P39: 0.105
O40: Tasa de impuesto por ganancia ocasional | P40: 0.15
B41: PPE (Propiedades, Planta y Equipo) Bruta | C41: =Datos!C10*1000000 -> 14000000000 | D41: =C41 -> 14000000000 | E41: =D41 -> 14000000000 | F41: =E41 -> 14000000000 | G41: =F41 -> 14000000000 | H41: =G41 -> 14000000000 | I41: =H41 -> 14000000000 | J41: =I41 -> 14000000000 | K41: =J41 -> 14000000000 | ... M41: =L41 -> 14000000000
B42: Depreciación acumulada | D42: =D22 -> 799800000 | E42: =E22 -> 799800000 | F42: =F22 -> 799800000 | G42: =G22 -> 799800000 | H42: =H22 -> 799800000 | I42: =I22 -> 799800000 | J42: =J22 -> 799800000 | K42: =K22 -> 799800000 | ... M42: =M22 -> 799800000 | O42: Valor en venta esperado | P42: =Datos!$C$10*1000000*P38 -> 4200000000
B43: PPE Neta | D43: =D41-D42 -> 13200200000 | E43: =D43-E42 -> 12400400000 | F43: =E43-F42 -> 11600600000 | G43: =F43-G42 -> 10800800000 | H43: =G43-H42 -> 10001000000 | I43: =H43-I42 -> 9201200000 | J43: =I43-J42 -> 8401400000 | K43: =J43-K42 -> 7601600000 | L43: =K43-L42 -> 6801800000 | M43: =L43-M42 -> 6002000000 | O43: Valor en libros | P43: =M43 -> 6002000000
O44: Utilidad neta | P44: =P42-P43 -> -1802000000
B45: Capital Invertido en la operación | D45: =D43+D38 -> 1.2983712e+10 | E45: =E43+E38 -> 8.6898369e+09 | F45: =F43+F38 -> 7.2679328e+09 | G45: =G43+G38 -> 5.7712608e+09 | H45: =H43+H38 -> 4.1905993e+09 | I45: =I43+I38 -> 2.5172319e+09 | J45: =J43+J38 -> 7.5240568e+08 | K45: =K43+K38 -> -1.1336447e+09 | ... M45: =M43+M38 -> -5.3548079e+09 | O45: Impuesto por ganancia ocasional | P45: =IF(P44<0,0,P44*P40) -> 0
O47: Flujo de caja por venta del activo | P47: =P42-P45 -> 4200000000
B48: FLUJO DE CAJA | C48: Año 0 | D48: Año 1 | E48: Año 2 | F48: Año 3 | G48: Año 4 | H48: Año 5 | I48: Año 6 | J48: Año 7 | K48: Año 8 | L48: Año 9 | M48: Año 10 | N48: Año 11 | O48: Disposición final | P48: =Datos!$C$10*'Estado de resultados'!P39*1000000 -> 1470000000
B49: EBIT | D49: =D26 -> 1313450000 | E49: =E26 -> 13283005800 | F49: =F26 -> 1.5639437e+10 | G49: =G26 -> 1.8302934e+10 | H49: =H26 -> 2.1311823e+10 | I49: =I26 -> 2.4703327e+10 | J49: =J26 -> 2.8478557e+10 | K49: =K26 -> 3.2752901e+10 | ... M49: =M26 -> 4.3139978e+10 | O49: Valor de salvamento | P49: =P47-P48 -> 2730000000
...

Sheet Breakeven Precio
B1: Año | C1: Año 0 | D1: Año 1 | E1: Año 2 | F1: Año 3 | G1: Año 4 | H1: Año 5 | I1: Año 6 | J1: Año 7 | K1: Año 8 | L1: Año 9 | M1: Año 10
B2: Consecutivo | C2: 0 | D2: 1 | E2: 2 | F2: 3 | G2: 4 | H2: 5 | I2: 6 | J2: 7 | K2: 8 | L2: 9 | M2: 10
B4: Inflación | D4: 0.0584 | E4: 0.0684 | F4: 0.0658 | G4: 0.0637 | H4: 0.06175 | I4: 0.0585 | J4: 0.05815 | K4: 0.0588 | L4: 0.0586 | M4: 0.0585
B5: Tasa de impuestos | D5: 0.35 | E5: 0.35 | F5: 0.35 | G5: 0.35 | H5: 0.35 | I5: 0.35 | J5: 0.35 | K5: 0.35 | L5: 0.35 | M5: 0.35
B8: Precio | C8: =(D8-'Estado de resultados'!D8)/'Estado de resultados'!D8 -> 0.49806619 | D8: 9737430.2 | E8: =D8*(1+D4)*(1+Datos!$C$31) -> 10924462 | F8: =E8*(1+E4)*(1+Datos!$C$31) -> 12371997 | G8: =F8*(1+F4)*(1+Datos!$C$31) -> 13977239 | H8: =G8*(1+G4)*(1+Datos!$C$31) -> 15759644 | I8: =H8*(1+H4)*(1+Datos!$C$31) -> 17736770 | J8: =I8*(1+I4)*(1+Datos!$C$31) -> 19900834 | K8: =J8*(1+J4)*(1+Datos!$C$31) -> 22321551 | L8: =K8*(1+K4)*(1+Datos!$C$31) -> 25052102 | M8: =L8*(1+L4)*(1+Datos!$C$31) -> 28111364
B9: Costo | D9: 2000000 | E9: =D9*(1+D4)*(1+Datos!$C$23) -> 2159136 | F9: =E9*(1+E4)*(1+Datos!$C$23) -> 2352957.3 | G9: =F9*(1+F4)*(1+Datos!$C$23) -> 2557937.6 | H9: =G9*(1+G4)*(1+Datos!$C$23) -> 2775295.7 | I9: =H9*(1+H4)*(1+Datos!$C$23) -> 3005603.7 | J9: =I9*(1+I4)*(1+Datos!$C$23) -> 3245060.1 | K9: =J9*(1+J4)*(1+Datos!$C$23) -> 3502435.5 | L9: =K9*(1+K4)*(1+Datos!$C$23) -> 3782546.3 | M9: =L9*(1+L4)*(1+Datos!$C$23) -> 4084287.6
B10: Cantidades | D10: 1000 | E10: 1000 | F10: 1000 | G10: 1500 | H10: 1500 | I10: 1500 | J10: 2500 | K10: 2500 | L10: 2500 | M10: 2500
B14: ESTADO DE RESULTADOS | C14: Año 0 | D14: Año 1 | E14: Año 2 | F14: Año 3 | G14: Año 4 | H14: Año 5 | I14: Año 6 | J14: Año 7 | K14: Año 8 | L14: Año 9 | M14: Año 10 | N14: Año 11
A15: =D15/$D$15 -> 1 | B15: Ingresos operacionales | D15: =D8*D10 -> 9.7374302e+09 | E15: =E8*E10 -> 1.0924462e+10 | F15: =F8*F10 -> 1.2371997e+10 | G15: =G8*G10 -> 2.0965858e+10 | H15: =H8*H10 -> 2.3639466e+10 | I15: =I8*I10 -> 2.6605155e+10 | J15: =J8*J10 -> 4.9752084e+10 | K15: =K8*K10 -> 5.5803878e+10 | ... M15: =M8*M10 -> 7.0278411e+10
A16: =D16/$D$15 -> 0.205393 | B16: Costo de ventas | D16: =D9*D10 -> 2000000000 | E16: =E9*E10 -> 2159136000 | F16: =F9*F10 -> 2.3529573e+09 | G16: =G9*G10 -> 3.8369063e+09 | H16: =H9*H10 -> 4.1629436e+09 | I16: =I9*I10 -> 4.5084055e+09 | J16: =J9*J10 -> 8.1126502e+09 | K16: =K9*K10 -> 8.7560889e+09 | ... M16: =M9*M10 -> 1.0210719e+10
A17: =D17/$D$15 -> 0.03080895 | B17: Costo de nómina asociada a la operación | D17: =Nómina!H3 -> 300000000 | E17: =D17*(1+D4) -> 317520000 | F17: =E17*(1+E4) -> 339238368 | G17: =F17*(1+F4) -> 3.6156025e+08 | H17: =G17*(1+G4) -> 3.8459164e+08 | I17: =H17*(1+H4) -> 4.0834017e+08 | J17: =I17*(1+I4) -> 4.3222807e+08 | K17: =J17*(1+J4) -> 4.5736214e+08 | L17: =K17*(1+K4) -> 4.8425503e+08 | M17: =L17*(1+L4) -> 5.1263238e+08
A18: =D18/$D$15 -> 0.055 | B18: Costo de mantenimiento | D18: =D15*Datos!$C$21 -> 5.3555866e+08 | E18: =E15*Datos!$C$21 -> 6.0084541e+08 | F18: =F15*Datos!$C$21 -> 6.8045983e+08 | G18: =G15*Datos!$C$21 -> 1.1531222e+09 | H18: =H15*Datos!$C$21 -> 1.3001706e+09 | I18: =I15*Datos!$C$21 -> 1.4632835e+09 | J18: =J15*Datos!$C$21 -> 2.7363646e+09 | K18: =K15*Datos!$C$21 -> 3.0692133e+09 | ... M18: =M15*Datos!$C$21 -> 3.8653126e+09
A19: =D19/$D$15 -> 0.70879805 | B19: Utilidad bruta | D19: =D15-D16-D17-D18 -> 6.9018716e+09 | E19: =E15-E16-E17-E18 -> 7.8469605e+09 | F19: =F15-F16-F17-F18 -> 8.9993413e+09 | G19: =G15-G16-G17-G18 -> 1.5614269e+10 | H19: =H15-H16-H17-H18 -> 1.779176e+10 | I19: =I15-I16-I17-I18 -> 2.0225126e+10 | J19: =J15-J16-J17-J18 -> 3.8470841e+10 | K19: =K15-K16-K17-K18 -> 4.3521214e+10 | ... M19: =M15-M16-M17-M18 -> 5.5689747e+10
A20: =D20/$D$15 -> 0.15281239 | B20: Costos de nómina administrativos | D20: =Nómina!H4 -> 1488000000 | E20: =D20*(1+D4) -> 1574899200 | F20: =E20*(1+E4) -> 1.6826223e+09 | G20: =F20*(1+F4) -> 1.7933389e+09 | H20: =G20*(1+G4) -> 1.9075745e+09 | I20: =H20*(1+H4) -> 2.0253673e+09 | J20: =I20*(1+I4) -> 2.1438513e+09 | K20: =J20*(1+J4) -> 2.2685162e+09 | L20: =K20*(1+K4) -> 2.401905e+09 | M20: =L20*(1+L4) -> 2.5426566e+09
A21: =D21/$D$15 -> 0.25 | B21: Gastos operacionales (variable) | D21: =D15*Datos!$C$26 -> 2.4343576e+09 | E21: =E15*Datos!$C$26 -> 2.7311155e+09 | F21: =F15*Datos!$C$26 -> 3.0929992e+09 | G21: =G15*Datos!$C$26 -> 5.2414645e+09 | H21: =H15*Datos!$C$26 -> 5.9098665e+09 | I21: =I15*Datos!$C$26 -> 6.6512889e+09 | J21: =J15*Datos!$C$26 -> 1.2438021e+10 | K21: =K15*Datos!$C$26 -> 1.3950969e+10 | ... M21: =M15*Datos!$C$26 -> 1.7569603e+10
A22: =D22/$D$15 -> 0.08213666 | B22: Depreciación | D22: {=Depreciaciones!B7:K7} -> 799800000 | E22: 799800000 | F22: 799800000 | G22: 799800000 | H22: 799800000 | I22: 799800000 | J22: 799800000 | K22: 799800000 | L22: 799800000 | M22: 799800000
A23: =D23/$D$15 -> 0.02875502 | B23: Amortización | D23: {='Amortización gasto seguro'!B4:K4} -> 280000000 | E23: 280000000 | F23: 280000000 | G23: 280000000 | H23: 280000000 | I23: 280000000 | J23: 280000000 | K23: 280000000 | L23: 280000000 | M23: 280000000
A24: =D24/$D$15 -> 0.02 | B24: Comisiones | D24: =D15*Datos!$C$27 -> 1.947486e+08 | E24: =E15*Datos!$C$27 -> 2.1848924e+08 | F24: =F15*Datos!$C$27 -> 2.4743994e+08 | G24: =G15*Datos!$C$27 -> 4.1931716e+08 | H24: =H15*Datos!$C$27 -> 4.7278932e+08 | I24: =I15*Datos!$C$27 -> 5.3210311e+08 | J24: =J15*Datos!$C$27 -> 9.9504168e+08 | K24: =K15*Datos!$C$27 -> 1.1160776e+09 | ... M24: =M15*Datos!$C$27 -> 1.4055682e+09
A25: =D25/$D$15 -> 0.17509398 | B25: EBIT | D25: =D19-D20-D21-D22-D23-D24 -> 1.7049654e+09 | E25: =E19-E20-E21-E22-E23-E24 -> 2.2426566e+09 | F25: =F19-F20-F21-F22-F23-F24 -> 2.8964799e+09 | G25: =G19-G20-G21-G22-G23-G24 -> 7.0803487e+09 | H25: =H19-H20-H21-H22-H23-H24 -> 8.4217299e+09 | I25: =I19-I20-I21-I22-I23-I24 -> 9.936567e+09 | J25: =J19-J20-J21-J22-J23-J24 -> 2.1814127e+10 | K25: =K19-K20-K21-K22-K23-K24 -> 2.510585e+10 | ... M25: =M19-M20-M21-M22-M23-M24 -> 3.3092119e+10
A26: =D26/$D$15 -> 0.18027296 | B26: Gastos financieros (intereses) | D26: {=TRANSPOSE(Bancos!L20:L29)*1000000} -> 1.7553954e+09 | E26: 2.5295681e+09 | F26: 2.3540285e+09 | G26: 2.178489e+09 | H26: 2.0029494e+09 | I26: 1.8274099e+09 | J26: 1.6518704e+09 | K26: 1.4763308e+09 | L26: 1.3007913e+09 | M26: 1.8994244e+09
A27: =D27/$D$15 -> -0.0051789811 | B27: EBT | D27: =D25-D26 -> -50429967 | E27: =E25-E26 -> -2.8691145e+08 | F27: =F25-F26 -> 5.4245136e+08 | G27: =G25-G26 -> 4.9018598e+09 | H27: =H25-H26 -> 6.4187805e+09 | I27: =I25-I26 -> 8.1091571e+09 | J27: =J25-J26 -> 2.0162257e+10 | K27: =K25-K26 -> 2.3629519e+10 | ... M27: =M25-M26 -> 3.1192695e+10
A28: =D28/$D$15 -> 0 | B28: Provisión de impuestos | D28: =IF(D27<0,0,D27*D5) -> 0 | E28: =IF(E27<0,0,E27*E5) -> 0 | F28: =IF(F27<0,0,F27*F5) -> 1.8985798e+08 | G28: =IF(G27<0,0,G27*G5) -> 1.7156509e+09 | H28: =IF(H27<0,0,H27*H5) -> 2.2465732e+09 | I28: =IF(I27<0,0,I27*I5) -> 2.838205e+09 | J28: =IF(J27<0,0,J27*J5) -> 7.0567899e+09 | K28: =IF(K27<0,0,K27*K5) -> 8.2703318e+09 | ... M28: =IF(M27<0,0,M27*M5) -> 1.0917443e+10
A29: =D29/$D$15 -> -0.0051789811 | B29: Utilidad neta | D29: =D27-D28 -> -50429967 | E29: =E27-E28 -> -2.8691145e+08 | F29: =F27-F28 -> 3.5259338e+08 | G29: =G27-G28 -> 3.1862088e+09 | H29: =H27-H28 -> 4.1722073e+09 | I29: =I27-I28 -> 5.2709521e+09 | J29: =J27-J28 -> 1.3105467e+10 | K29: =K27-K28 -> 1.5359188e+10 | ... M29: =M27-M28 -> 2.0275252e+10
B31: EBITDA | D31: =D25+D22+D23 -> 2.7847654e+09 | E31: =E25+E22+E23 -> 3.3224566e+09 | F31: =F25+F22+F23 -> 3.9762799e+09 | G31: =G25+G22+G23 -> 8.1601487e+09 | H31: =H25+H22+H23 -> 9.5015299e+09 | I31: =I25+I22+I23 -> 1.1016367e+10 | J31: =J25+J22+J23 -> 2.2893927e+10 | K31: =K25+K22+K23 -> 2.618565e+10 | ... M31: =M25+M22+M23 -> 3.4171919e+10
A33: =D33/$D$15 -> 0.083333333 | B33: CXC | D33: =(Datos!$C$28/360)*'Breakeven Precio'!D15 -> 8.1145252e+08 | E33: =(Datos!$C$28/360)*'Breakeven Precio'!E15 -> 9.1037183e+08 | F33: =(Datos!$C$28/360)*'Breakeven Precio'!F15 -> 1.0309997e+09 | G33: =(Datos!$C$28/360)*'Breakeven Precio'!G15 -> 1.7471548e+09 | H33: =(Datos!$C$28/360)*'Breakeven Precio'!H15 -> 1.9699555e+09 | I33: =(Datos!$C$28/360)*'Breakeven Precio'!I15 -> 2.2170963e+09 | J33: =(Datos!$C$28/360)*'Breakeven Precio'!J15 -> 4.146007e+09 | K33: =(Datos!$C$28/360)*'Breakeven Precio'!K15 -> 4.6503231e+09 | ... M33: =(Datos!$C$28/360)*'Breakeven Precio'!M15 -> 5.8565342e+09
B34: KTO | D34: =D33 -> 8.1145252e+08 | E34: =E33 -> 9.1037183e+08 | F34: =F33 -> 1.0309997e+09 | G34: =G33 -> 1.7471548e+09 | H34: =H33 -> 1.9699555e+09 | I34: =I33 -> 2.2170963e+09 | J34: =J33 -> 4.146007e+09 | K34: =K33 -> 4.6503231e+09 | ... M34: =M33 -> 5.8565342e+09
A35: =D35/$D$15 -> 0.05134825 | B35: CXP | D35: =(Datos!$C$29/360)*'Breakeven Precio'!D16 -> 500000000 | E35: =(Datos!$C$29/360)*'Breakeven Precio'!E16 -> 539784000 | F35: =(Datos!$C$29/360)*'Breakeven Precio'!F16 -> 5.8823933e+08 | G35: =(Datos!$C$29/360)*'Breakeven Precio'!G16 -> 9.5922658e+08 | H35: =(Datos!$C$29/360)*'Breakeven Precio'!H16 -> 1.0407359e+09 | I35: =(Datos!$C$29/360)*'Breakeven Precio'!I16 -> 1.1271014e+09 | J35: =(Datos!$C$29/360)*'Breakeven Precio'!J16 -> 2.0281626e+09 | K35: =(Datos!$C$29/360)*'Breakeven Precio'!K16 -> 2.1890222e+09 | ... M35: =(Datos!$C$29/360)*'Breakeven Precio'!M16 -> 2.5526798e+09
A36: =D36/$D$15 -> 0 | B36: Impuestos por pagar | D36: =D28 -> 0 | E36: =E28 -> 0 | F36: =F28 -> 1.8985798e+08 | G36: =G28 -> 1.7156509e+09 | H36: =H28 -> 2.2465732e+09 | I36: =I28 -> 2.838205e+09 | J36: =J28 -> 7.0567899e+09 | K36: =K28 -> 8.2703318e+09 | ... M36: =M28 -> 1.0917443e+10
